Workbook

Sheet SETTINGS
B1: ⚙ BEST TIME MARKETING — SETTINGS & MASTER LISTS
B3: 📁 PROJECTS LIST | G3: 📋 DROPDOWN LISTS
B4: Project Code | C4: Project Name | D4: Location | E4: Total Units | G4: REGISTRY STATUS | H4: Done | I4: Not Done | J4: Late
B5: GRE | C5: Green Valley | D5: Lahore | E5: 200 | G5: FBR STATUS | H5: Paid | I5: Pending | J5: Exempt | K5: N/A
B6: SKY | C6: Sky Heights | D6: Islamabad | E6: 150 | G6: PAYMENT TYPE | H6: Cash | I6: Installment
B7: SUN | C7: Sunrise City | D7: Karachi | E7: 300 | G7: RES/COMM | H7: Residential | I7: Commercial
B8: BTM | C8: BTM Residencia | D8: Rawalpindi | E8: 180 | G8: BUBBLE OPTION | H8: Pay After 6 Months | I8: Adjust in Plan | J8: Waived
B9: ELI | C9: Elite Gardens | D9: Faisalabad | E9: 120 | G9: RELATION | H9: Son | I9: Daughter | J9: Spouse | K9: Father | L9: Mother | M9: Brother | N9: Sister | O9: Other
B11: 👤 SALESMEN LIST
B12: Salesman Name | C12: Fixed Salary | D12: Commission/Deal
B13: Ahmed Raza | C13: 3000000 | D13: 50000
B14: Bilal Shah | C14: 2500000 | D14: 40000
B15: Usman Iqbal | C15: 2000000 | D15: 35000

Sheet DATA ENTRY
A1: 🏢 BEST TIME MARKETING — CLIENT DATA ENTRY SHEET | Data Entry Operators: Fill BLUE cells only
A2: 📋 | B2: 🆔 AUTO ID | C2: 🏗 PLOT / DEAL DETAILS | K2: 💰 PAYMENT PLAN | S2: 👤 APPLICANT INFO | X2: 🪪 NOMINEE 1 | AE2: 🪪 NOMINEE 2 | AI2: 🤝 DEALER | AM2: 💼 SALESMAN | AO2: 📜 REGISTRY | AR2: 🏛 FBR TAX | AU2: 📅 META
A3: Row # | B3: Unique Deal ID | C3: Project | D3: Dare / Block | E3: Plot No. | F3: Size (Marla) | G3: Res / Comm | H3: Payment Type | I3: Per Marla Rate (PKR) | J3: Total Amount (PKR) | K3: Token/Advance (PKR) | L3: Installment Months | M3: Monthly Instalment (PKR) | N3: Bubble Payment (PKR) | O3: Bubble Option | P3: Total Paid (PKR) | Q3: Balance (PKR) | R3: Payment Status | S3: Applicant Name | T3: Father's Name | U3: Address | V3: CNIC No. | W3: Mobile No. | X3: Nominee Name | Y3: Relation | Z3: Nom. Father Name | AA3: Nominee CNIC | AB3: Nominee Mobile | AC3: Nominee Share % | AD3: Nominee 2 Name | AE3: Nom2 Relation | AF3: Nom2 CNIC | AG3: Nom2 Share % | AH3: Dealer Name | AI3: Dealer Mobile | AJ3: Agency Name | AK3: Commission (PKR) | AL3: Salesman Name | AM3: Salesman Commission (PKR) | AN3: Registry Status | AO3: Registry Date | AP3: Registry Remarks | AQ3: Seller FBR | AR3: Buyer FBR | AS3: FBR Token/Ref | AT3: Booking Date | AU3: Operator Name | AV3: Remarks
A4: 1 | B4: =IF(C4="","",IF(E4="","",IFERROR("BTM-"&LEFT(C4,3)&"-"&E4&"-"&TEXT(TODAY(),"YY")&"-"&TEXT(A4,"000"),""))) | J4: =IF(F4="","",IF(I4="","",F4*I4)) | M4: =IF(OR(J4="",L4="",K4=""),"",IFERROR((J4-K4-IF(O4="Adjust in Plan",N4,0))/L4,"-")) | P4: =IFERROR(SUMIF(INSTALMENTS!$C:$C,B4,INSTALMENTS!$I:$I),0) -> 0 | Q4: =IF(J4="","",J4-P4) | R4: =IF(J4="","",IF(Q4<=0,"✅ Completed",IF(IFERROR(SUMPRODUCT((INSTALMENTS!$C:$C=B4)*(INSTALMENTS!$F:$F<TODAY())*(INSTALMENTS!$I:$I<INSTALMENTS!$H:$H)),0)>0,"🔴 Overdue","🟢 Active")))
A5: 2 | B5: =IF(C5="","",IF(E5="","",IFERROR("BTM-"&LEFT(C5,3)&"-"&E5&"-"&TEXT(TODAY(),"YY")&"-"&TEXT(A5,"000"),""))) | J5: =IF(F5="","",IF(I5="","",F5*I5)) | M5: =IF(OR(J5="",L5="",K5=""),"",IFERROR((J5-K5-IF(O5="Adjust in Plan",N5,0))/L5,"-")) | P5: =IFERROR(SUMIF(INSTALMENTS!$C:$C,B5,INSTALMENTS!$I:$I),0) -> 0 | Q5: =IF(J5="","",J5-P5) | R5: =IF(J5="","",IF(Q5<=0,"✅ Completed",IF(IFERROR(SUMPRODUCT((INSTALMENTS!$C:$C=B5)*(INSTALMENTS!$F:$F<TODAY())*(INSTALMENTS!$I:$I<INSTALMENTS!$H:$H)),0)>0,"🔴 Overdue","🟢 Active")))
A6: 3 | B6: =IF(C6="","",IF(E6="","",IFERROR("BTM-"&LEFT(C6,3)&"-"&E6&"-"&TEXT(TODAY(),"YY")&"-"&TEXT(A6,"000"),""))) | J6: =IF(F6="","",IF(I6="","",F6*I6)) | M6: =IF(OR(J6="",L6="",K6=""),"",IFERROR((J6-K6-IF(O6="Adjust in Plan",N6,0))/L6,"-")) | P6: =IFERROR(SUMIF(INSTALMENTS!$C:$C,B6,INSTALMENTS!$I:$I),0) -> 0 | Q6: =IF(J6="","",J6-P6) | R6: =IF(J6="","",IF(Q6<=0,"✅ Completed",IF(IFERROR(SUMPRODUCT((INSTALMENTS!$C:$C=B6)*(INSTALMENTS!$F:$F<TODAY())*(INSTALMENTS!$I:$I<INSTALMENTS!$H:$H)),0)>0,"🔴 Overdue","🟢 Active")))
A7: 4 | B7: =IF(C7="","",IF(E7="","",IFERROR("BTM-"&LEFT(C7,3)&"-"&E7&"-"&TEXT(TODAY(),"YY")&"-"&TEXT(A7,"000"),""))) | J7: =IF(F7="","",IF(I7="","",F7*I7)) | M7: =IF(OR(J7="",L7="",K7=""),"",IFERROR((J7-K7-IF(O7="Adjust in Plan",N7,0))/L7,"-")) | P7: =IFERROR(SUMIF(INSTALMENTS!$C:$C,B7,INSTALMENTS!$I:$I),0) -> 0 | Q7: =IF(J7="","",J7-P7) | R7: =IF(J7="","",IF(Q7<=0,"✅ Completed",IF(IFERROR(SUMPRODUCT((INSTALMENTS!$C:$C=B7)*(INSTALMENTS!$F:$F<TODAY())*(INSTALMENTS!$I:$I<INSTALMENTS!$H:$H)),0)>0,"🔴 Overdue","🟢 Active")))
A8: 5 | B8: =IF(C8="","",IF(E8="","",IFERROR("BTM-"&LEFT(C8,3)&"-"&E8&"-"&TEXT(TODAY(),"YY")&"-"&TEXT(A8,"000"),""))) | J8: =IF(F8="","",IF(I8="","",F8*I8)) | M8: =IF(OR(J8="",L8="",K8=""),"",IFERROR((J8-K8-IF(O8="Adjust in Plan",N8,0))/L8,"-")) | P8: =IFERROR(SUMIF(INSTALMENTS!$C:$C,B8,INSTALMENTS!$I:$I),0) -> 0 | Q8: =IF(J8="","",J8-P8) | R8: =IF(J8="","",IF(Q8<=0,"✅ Completed",IF(IFERROR(SUMPRODUCT((INSTALMENTS!$C:$C=B8)*(INSTALMENTS!$F:$F<TODAY())*(INSTALMENTS!$I:$I<INSTALMENTS!$H:$H)),0)>0,"🔴 Overdue","🟢 Active")))
A9: 6 | B9: =IF(C9="","",IF(E9="","",IFERROR("BTM-"&LEFT(C9,3)&"-"&E9&"-"&TEXT(TODAY(),"YY")&"-"&TEXT(A9,"000"),""))) | J9: =IF(F9="","",IF(I9="","",F9*I9)) | M9: =IF(OR(J9="",L9="",K9=""),"",IFERROR((J9-K9-IF(O9="Adjust in Plan",N9,0))/L9,"-")) | P9: =IFERROR(SUMIF(INSTALMENTS!$C:$C,B9,INSTALMENTS!$I:$I),0) -> 0 | Q9: =IF(J9="","",J9-P9) | R9: =IF(J9="","",IF(Q9<=0,"✅ Completed",IF(IFERROR(SUMPRODUCT((INSTALMENTS!$C:$C=B9)*(INSTALMENTS!$F:$F<TODAY())*(INSTALMENTS!$I:$I<INSTALMENTS!$H:$H)),0)>0,"🔴 Overdue","🟢 Active")))
A10: 7 | B10: =IF(C10="","",IF(E10="","",IFERROR("BTM-"&LEFT(C10,3)&"-"&E10&"-"&TEXT(TODAY(),"YY")&"-"&TEXT(A10,"000"),""))) | J10: =IF(F10="","",IF(I10="","",F10*I10)) | M10: =IF(OR(J10="",L10="",K10=""),"",IFERROR((J10-K10-IF(O10="Adjust in Plan",N10,0))/L10,"-")) | P10: =IFERROR(SUMIF(INSTALMENTS!$C:$C,B10,INSTALMENTS!$I:$I),0) -> 0 | Q10: =IF(J10="","",J10-P10) | R10: =IF(J10="","",IF(Q10<=0,"✅ Completed",IF(IFERROR(SUMPRODUCT((INSTALMENTS!$C:$C=B10)*(INSTALMENTS!$F:$F<TODAY())*(INSTALMENTS!$I:$I<INSTALMENTS!$H:$H)),0)>0,"🔴 Overdue","🟢 Active")))
A11: 8 | B11: =IF(C11="","",IF(E11="","",IFERROR("BTM-"&LEFT(C11,3)&"-"&E11&"-"&TEXT(TODAY(),"YY")&"-"&TEXT(A11,"000"),""))) | J11: =IF(F11="","",IF(I11="","",F11*I11)) | M11: =IF(OR(J11="",L11="",K11=""),"",IFERROR((J11-K11-IF(O11="Adjust in Plan",N11,0))/L11,"-")) | P11: =IFERROR(SUMIF(INSTALMENTS!$C:$C,B11,INSTALMENTS!$I:$I),0) -> 0 | Q11: =IF(J11="","",J11-P11) | R11: =IF(J11="","",IF(Q11<=0,"✅ Completed",IF(IFERROR(SUMPRODUCT((INSTALMENTS!$C:$C=B11)*(INSTALMENTS!$F:$F<TODAY())*(INSTALMENTS!$I:$I<INSTALMENTS!$H:$H)),0)>0,"🔴 Overdue","🟢 Active")))
A12: 9 | B12: =IF(C12="","",IF(E12="","",IFERROR("BTM-"&LEFT(C12,3)&"-"&E12&"-"&TEXT(TODAY(),"YY")&"-"&TEXT(A12,"000"),""))) | J12: =IF(F12="","",IF(I12="","",F12*I12)) | M12: =IF(OR(J12="",L12="",K12=""),"",IFERROR((J12-K12-IF(O12="Adjust in Plan",N12,0))/L12,"-")) | P12: =IFERROR(SUMIF(INSTALMENTS!$C:$C,B12,INSTALMENTS!$I:$I),0) -> 0 | Q12: =IF(J12="","",J12-P12) | R12: =IF(J12="","",IF(Q12<=0,"✅ Completed",IF(IFERROR(SUMPRODUCT((INSTALMENTS!$C:$C=B12)*(INSTALMENTS!$F:$F<TODAY())*(INSTALMENTS!$I:$I<INSTALMENTS!$H:$H)),0)>0,"🔴 Overdue","🟢 Active")))
A13: 10 | B13: =IF(C13="","",IF(E13="","",IFERROR("BTM-"&LEFT(C13,3)&"-"&E13&"-"&TEXT(TODAY(),"YY")&"-"&TEXT(A13,"000"),""))) | J13: =IF(F13="","",IF(I13="","",F13*I13)) | M13: =IF(OR(J13="",L13="",K13=""),"",IFERROR((J13-K13-IF(O13="Adjust in Plan",N13,0))/L13,"-")) | P13: =IFERROR(SUMIF(INSTALMENTS!$C:$C,B13,INSTALMENTS!$I:$I),0) -> 0 | Q13: =IF(J13="","",J13-P13) | R13: =IF(J13="","",IF(Q13<=0,"✅ Completed",IF(IFERROR(SUMPRODUCT((INSTALMENTS!$C:$C=B13)*(INSTALMENTS!$F:$F<TODAY())*(INSTALMENTS!$I:$I<INSTALMENTS!$H:$H)),0)>0,"🔴 Overdue","🟢 Active")))
A14: 11 | B14: =IF(C14="","",IF(E14="","",IFERROR("BTM-"&LEFT(C14,3)&"-"&E14&"-"&TEXT(TODAY(),"YY")&"-"&TEXT(A14,"000"),""))) | J14: =IF(F14="","",IF(I14="","",F14*I14)) | M14: =IF(OR(J14="",L14="",K14=""),"",IFERROR((J14-K14-IF(O14="Adjust in Plan",N14,0))/L14,"-")) | P14: =IFERROR(SUMIF(INSTALMENTS!$C:$C,B14,INSTALMENTS!$I:$I),0) -> 0 | Q14: =IF(J14="","",J14-P14) | R14: =IF(J14="","",IF(Q14<=0,"✅ Completed",IF(IFERROR(SUMPRODUCT((INSTALMENTS!$C:$C=B14)*(INSTALMENTS!$F:$F<TODAY())*(INSTALMENTS!$I:$I<INSTALMENTS!$H:$H)),0)>0,"🔴 Overdue","🟢 Active")))
A15: 12 | B15: =IF(C15="","",IF(E15="","",IFERROR("BTM-"&LEFT(C15,3)&"-"&E15&"-"&TEXT(TODAY(),"YY")&"-"&TEXT(A15,"000"),""))) | J15: =IF(F15="","",IF(I15="","",F15*I15)) | M15: =IF(OR(J15="",L15="",K15=""),"",IFERROR((J15-K15-IF(O15="Adjust in Plan",N15,0))/L15,"-")) | P15: =IFERROR(SUMIF(INSTALMENTS!$C:$C,B15,INSTALMENTS!$I:$I),0) -> 0 | Q15: =IF(J15="","",J15-P15) | R15: =IF(J15="","",IF(Q15<=0,"✅ Completed",IF(IFERROR(SUMPRODUCT((INSTALMENTS!$C:$C=B15)*(INSTALMENTS!$F:$F<TODAY())*(INSTALMENTS!$I:$I<INSTALMENTS!$H:$H)),0)>0,"🔴 Overdue","🟢 Active")))
... A203: 200 | B203: =IF(C203="","",IF(E203="","",IFERROR("BTM-"&LEFT(C203,3)&"-"&E203&"-"&TEXT(TODAY(),"YY")&"-"&TEXT(A203,"000"),""))) | J203: =IF(F203="","",IF(I203="","",F203*I203)) | M203: =IF(OR(J203="",L203="",K203=""),"",IFERROR((J203-K203-IF(O203="Adjust in Plan",N203,0))/L203,"-")) | P203: =IFERROR(SUMIF(INSTALMENTS!$C:$C,B203,INSTALMENTS!$I:$I),0) -> 0 | Q203: =IF(J203="","",J203-P203) | R203: =IF(J203="","",IF(Q203<=0,"✅ Completed",IF(IFERROR(SUMPRODUCT((INSTALMENTS!$C:$C=B203)*(INSTALMENTS!$F:$F<TODAY())*(INSTALMENTS!$I:$I<INSTALMENTS!$H:$H)),0)>0,"🔴 Overdue","🟢 Active")))

Sheet INSTALMENTS
A1: 💰 INSTALMENTS TRACKER — Enter Deal ID in col C to auto-fill client info. Log each payment received.
A2: Inst. # | B2: Month | C2: Deal ID | D2: Applicant Name | E2: Project | F2: Plot No. | G2: Due Date | H2: Amount Due (PKR) | I2: Amount Paid(PKR) | J2: Payment Date | K2: Shortfall (PKR) | L2: Status
A3: 1 | D3: =IFERROR(INDEX('DATA ENTRY'!$S:$S,MATCH(C3,'DATA ENTRY'!$B:$B,0)),"") -> 0 | E3: =IFERROR(INDEX('DATA ENTRY'!$C:$C,MATCH(C3,'DATA ENTRY'!$B:$B,0)),"") -> 0 | F3: =IFERROR(INDEX('DATA ENTRY'!$E:$E,MATCH(C3,'DATA ENTRY'!$B:$B,0)),"") -> 0 | K3: =IF(H3="","",MAX(0,H3-IF(I3="",0,I3))) | L3: =IF(H3="","",IF(I3>=H3,"✅ Paid",IF(G3<TODAY(),"🔴 Overdue",IF(G3<=TODAY()+90,"🟡 Due Soon","⬜ Upcoming"))))
A4: 2 | D4: =IFERROR(INDEX('DATA ENTRY'!$S:$S,MATCH(C4,'DATA ENTRY'!$B:$B,0)),"") -> 0 | E4: =IFERROR(INDEX('DATA ENTRY'!$C:$C,MATCH(C4,'DATA ENTRY'!$B:$B,0)),"") -> 0 | F4: =IFERROR(INDEX('DATA ENTRY'!$E:$E,MATCH(C4,'DATA ENTRY'!$B:$B,0)),"") -> 0 | K4: =IF(H4="","",MAX(0,H4-IF(I4="",0,I4))) | L4: =IF(H4="","",IF(I4>=H4,"✅ Paid",IF(G4<TODAY(),"🔴 Overdue",IF(G4<=TODAY()+90,"🟡 Due Soon","⬜ Upcoming"))))
A5: 3 | D5: =IFERROR(INDEX('DATA ENTRY'!$S:$S,MATCH(C5,'DATA ENTRY'!$B:$B,0)),"") -> 0 | E5: =IFERROR(INDEX('DATA ENTRY'!$C:$C,MATCH(C5,'DATA ENTRY'!$B:$B,0)),"") -> 0 | F5: =IFERROR(INDEX('DATA ENTRY'!$E:$E,MATCH(C5,'DATA ENTRY'!$B:$B,0)),"") -> 0 | K5: =IF(H5="","",MAX(0,H5-IF(I5="",0,I5))) | L5: =IF(H5="","",IF(I5>=H5,"✅ Paid",IF(G5<TODAY(),"🔴 Overdue",IF(G5<=TODAY()+90,"🟡 Due Soon","⬜ Upcoming"))))
A6: 4 | D6: =IFERROR(INDEX('DATA ENTRY'!$S:$S,MATCH(C6,'DATA ENTRY'!$B:$B,0)),"") -> 0 | E6: =IFERROR(INDEX('DATA ENTRY'!$C:$C,MATCH(C6,'DATA ENTRY'!$B:$B,0)),"") -> 0 | F6: =IFERROR(INDEX('DATA ENTRY'!$E:$E,MATCH(C6,'DATA ENTRY'!$B:$B,0)),"") -> 0 | K6: =IF(H6="","",MAX(0,H6-IF(I6="",0,I6))) | L6: =IF(H6="","",IF(I6>=H6,"✅ Paid",IF(G6<TODAY(),"🔴 Overdue",IF(G6<=TODAY()+90,"🟡 Due Soon","⬜ Upcoming"))))
A7: 5 | D7: =IFERROR(INDEX('DATA ENTRY'!$S:$S,MATCH(C7,'DATA ENTRY'!$B:$B,0)),"") -> 0 | E7: =IFERROR(INDEX('DATA ENTRY'!$C:$C,MATCH(C7,'DATA ENTRY'!$B:$B,0)),"") -> 0 | F7: =IFERROR(INDEX('DATA ENTRY'!$E:$E,MATCH(C7,'DATA ENTRY'!$B:$B,0)),"") -> 0 | K7: =IF(H7="","",MAX(0,H7-IF(I7="",0,I7))) | L7: =IF(H7="","",IF(I7>=H7,"✅ Paid",IF(G7<TODAY(),"🔴 Overdue",IF(G7<=TODAY()+90,"🟡 Due Soon","⬜ Upcoming"))))
A8: 6 | D8: =IFERROR(INDEX('DATA ENTRY'!$S:$S,MATCH(C8,'DATA ENTRY'!$B:$B,0)),"") -> 0 | E8: =IFERROR(INDEX('DATA ENTRY'!$C:$C,MATCH(C8,'DATA ENTRY'!$B:$B,0)),"") -> 0 | F8: =IFERROR(INDEX('DATA ENTRY'!$E:$E,MATCH(C8,'DATA ENTRY'!$B:$B,0)),"") -> 0 | K8: =IF(H8="","",MAX(0,H8-IF(I8="",0,I8))) | L8: =IF(H8="","",IF(I8>=H8,"✅ Paid",IF(G8<TODAY(),"🔴 Overdue",IF(G8<=TODAY()+90,"🟡 Due Soon","⬜ Upcoming"))))
A9: 7 | D9: =IFERROR(INDEX('DATA ENTRY'!$S:$S,MATCH(C9,'DATA ENTRY'!$B:$B,0)),"") -> 0 | E9: =IFERROR(INDEX('DATA ENTRY'!$C:$C,MATCH(C9,'DATA ENTRY'!$B:$B,0)),"") -> 0 | F9: =IFERROR(INDEX('DATA ENTRY'!$E:$E,MATCH(C9,'DATA ENTRY'!$B:$B,0)),"") -> 0 | K9: =IF(H9="","",MAX(0,H9-IF(I9="",0,I9))) | L9: =IF(H9="","",IF(I9>=H9,"✅ Paid",IF(G9<TODAY(),"🔴 Overdue",IF(G9<=TODAY()+90,"🟡 Due Soon","⬜ Upcoming"))))
A10: 8 | D10: =IFERROR(INDEX('DATA ENTRY'!$S:$S,MATCH(C10,'DATA ENTRY'!$B:$B,0)),"") -> 0 | E10: =IFERROR(INDEX('DATA ENTRY'!$C:$C,MATCH(C10,'DATA ENTRY'!$B:$B,0)),"") -> 0 | F10: =IFERROR(INDEX('DATA ENTRY'!$E:$E,MATCH(C10,'DATA ENTRY'!$B:$B,0)),"") -> 0 | K10: =IF(H10="","",MAX(0,H10-IF(I10="",0,I10))) | L10: =IF(H10="","",IF(I10>=H10,"✅ Paid",IF(G10<TODAY(),"🔴 Overdue",IF(G10<=TODAY()+90,"🟡 Due Soon","⬜ Upcoming"))))
A11: 9 | D11: =IFERROR(INDEX('DATA ENTRY'!$S:$S,MATCH(C11,'DATA ENTRY'!$B:$B,0)),"") -> 0 | E11: =IFERROR(INDEX('DATA ENTRY'!$C:$C,MATCH(C11,'DATA ENTRY'!$B:$B,0)),"") -> 0 | F11: =IFERROR(INDEX('DATA ENTRY'!$E:$E,MATCH(C11,'DATA ENTRY'!$B:$B,0)),"") -> 0 | K11: =IF(H11="","",MAX(0,H11-IF(I11="",0,I11))) | L11: =IF(H11="","",IF(I11>=H11,"✅ Paid",IF(G11<TODAY(),"🔴 Overdue",IF(G11<=TODAY()+90,"🟡 Due Soon","⬜ Upcoming"))))
A12: 10 | D12: =IFERROR(INDEX('DATA ENTRY'!$S:$S,MATCH(C12,'DATA ENTRY'!$B:$B,0)),"") -> 0 | E12: =IFERROR(INDEX('DATA ENTRY'!$C:$C,MATCH(C12,'DATA ENTRY'!$B:$B,0)),"") -> 0 | F12: =IFERROR(INDEX('DATA ENTRY'!$E:$E,MATCH(C12,'DATA ENTRY'!$B:$B,0)),"") -> 0 | K12: =IF(H12="","",MAX(0,H12-IF(I12="",0,I12))) | L12: =IF(H12="","",IF(I12>=H12,"✅ Paid",IF(G12<TODAY(),"🔴 Overdue",IF(G12<=TODAY()+90,"🟡 Due Soon","⬜ Upcoming"))))
A13: 11 | D13: =IFERROR(INDEX('DATA ENTRY'!$S:$S,MATCH(C13,'DATA ENTRY'!$B:$B,0)),"") -> 0 | E13: =IFERROR(INDEX('DATA ENTRY'!$C:$C,MATCH(C13,'DATA ENTRY'!$B:$B,0)),"") -> 0 | F13: =IFERROR(INDEX('DATA ENTRY'!$E:$E,MATCH(C13,'DATA ENTRY'!$B:$B,0)),"") -> 0 | K13: =IF(H13="","",MAX(0,H13-IF(I13="",0,I13))) | L13: =IF(H13="","",IF(I13>=H13,"✅ Paid",IF(G13<TODAY(),"🔴 Overdue",IF(G13<=TODAY()+90,"🟡 Due Soon","⬜ Upcoming"))))
A14: 12 | D14: =IFERROR(INDEX('DATA ENTRY'!$S:$S,MATCH(C14,'DATA ENTRY'!$B:$B,0)),"") -> 0 | E14: =IFERROR(INDEX('DATA ENTRY'!$C:$C,MATCH(C14,'DATA ENTRY'!$B:$B,0)),"") -> 0 | F14: =IFERROR(INDEX('DATA ENTRY'!$E:$E,MATCH(C14,'DATA ENTRY'!$B:$B,0)),"") -> 0 | K14: =IF(H14="","",MAX(0,H14-IF(I14="",0,I14))) | L14: =IF(H14="","",IF(I14>=H14,"✅ Paid",IF(G14<TODAY(),"🔴 Overdue",IF(G14<=TODAY()+90,"🟡 Due Soon","⬜ Upcoming"))))
... A502: 500 | D502: =IFERROR(INDEX('DATA ENTRY'!$S:$S,MATCH(C502,'DATA ENTRY'!$B:$B,0)),"") -> 0 | E502: =IFERROR(INDEX('DATA ENTRY'!$C:$C,MATCH(C502,'DATA ENTRY'!$B:$B,0)),"") -> 0 | F502: =IFERROR(INDEX('DATA ENTRY'!$E:$E,MATCH(C502,'DATA ENTRY'!$B:$B,0)),"") -> 0 | K502: =IF(H502="","",MAX(0,H502-IF(I502="",0,I502))) | L502: =IF(H502="","",IF(I502>=H502,"✅ Paid",IF(G502<TODAY(),"🔴 Overdue",IF(G502<=TODAY()+90,"🟡 Due Soon","⬜ Upcoming"))))

Sheet PAYMENT SCHEDULE
A1: 📅 PAYMENT SCHEDULE GENERATOR — Type a Deal ID in B4 to auto-generate full schedule
B4: Deal ID
B5: Client Name | D5: =IFERROR(INDEX('DATA ENTRY'!$S:$S,MATCH(C4,'DATA ENTRY'!$B:$B,0)),"") -> 0
B6: Project | D6: =IFERROR(INDEX('DATA ENTRY'!$C:$C,MATCH(C4,'DATA ENTRY'!$B:$B,0)),"") -> 0
B7: Plot No. | D7: =IFERROR(INDEX('DATA ENTRY'!$E:$E,MATCH(C4,'DATA ENTRY'!$B:$B,0)),"") -> 0
B8: Total Price | D8: =IFERROR(INDEX('DATA ENTRY'!$J:$J,MATCH(C4,'DATA ENTRY'!$B:$B,0)),"")
B9: Advance | D9: =IFERROR(INDEX('DATA ENTRY'!$K:$K,MATCH(C4,'DATA ENTRY'!$B:$B,0)),"") -> 0
B10: Monthly Inst. | D10: =IFERROR(INDEX('DATA ENTRY'!$M:$M,MATCH(C4,'DATA ENTRY'!$B:$B,0)),"")
B11: Bubble Payment | D11: =IFERROR(INDEX('DATA ENTRY'!$N:$N,MATCH(C4,'DATA ENTRY'!$B:$B,0)),"") -> 0
B12: Total Months | D12: =IFERROR(INDEX('DATA ENTRY'!$L:$L,MATCH(C4,'DATA ENTRY'!$B:$B,0)),"") -> 0
B13: Booking Date | D13: =IFERROR(INDEX('DATA ENTRY'!$AU:$AU,MATCH(C4,'DATA ENTRY'!$B:$B,0)),"") -> 0
B15: # | C15: Type | D15: Description | E15: Due Date | F15: Amount Due (PKR) | G15: Amount Paid (PKR) | H15: Balance (PKR) | I15: Notes
B16: 0 | C16: Token / Advance | E16: =IFERROR(D9,"") -> 0
B17: 1 | C17: =IF(D12="","",IF(1>D12,"","Monthly Instalment "&1)) | D17: =IFERROR(IF(D13="","",DATE(YEAR(D13),MONTH(D13)+1,DAY(D13))),"") | E17: =IF(D10="","",IF(1>D12,"",D10))
B18: 2 | C18: =IF(D12="","",IF(2>D12,"","Monthly Instalment "&2)) | D18: =IFERROR(IF(D13="","",DATE(YEAR(D13),MONTH(D13)+2,DAY(D13))),"") | E18: =IF(D10="","",IF(2>D12,"",D10))
B19: 3 | C19: =IF(D12="","",IF(3>D12,"","Monthly Instalment "&3)) | D19: =IFERROR(IF(D13="","",DATE(YEAR(D13),MONTH(D13)+3,DAY(D13))),"") | E19: =IF(D10="","",IF(3>D12,"",D10))
B20: 4 | C20: =IF(D12="","",IF(4>D12,"","Monthly Instalment "&4)) | D20: =IFERROR(IF(D13="","",DATE(YEAR(D13),MONTH(D13)+4,DAY(D13))),"") | E20: =IF(D10="","",IF(4>D12,"",D10))
B21: 5 | C21: =IF(D12="","",IF(5>D12,"","Monthly Instalment "&5)) | D21: =IFERROR(IF(D13="","",DATE(YEAR(D13),MONTH(D13)+5,DAY(D13))),"") | E21: =IF(D10="","",IF(5>D12,"",D10))
B22: 6 | C22: =IF(D12="","",IF(6>D12,"","Monthly Instalment "&6)) | D22: =IFERROR(IF(D13="","",DATE(YEAR(D13),MONTH(D13)+6,DAY(D13))),"") | E22: =IF(D10="","",IF(6>D12,"",D10))
B23: 7 | C23: =IF(D12="","",IF(7>D12,"","Monthly Instalment "&7)) | D23: =IFERROR(IF(D13="","",DATE(YEAR(D13),MONTH(D13)+7,DAY(D13))),"") | E23: =IF(D10="","",IF(7>D12,"",D10))
B24: 8 | C24: =IF(D12="","",IF(8>D12,"","Monthly Instalment "&8)) | D24: =IFERROR(IF(D13="","",DATE(YEAR(D13),MONTH(D13)+8,DAY(D13))),"") | E24: =IF(D10="","",IF(8>D12,"",D10))
B25: 9 | C25: =IF(D12="","",IF(9>D12,"","Monthly Instalment "&9)) | D25: =IFERROR(IF(D13="","",DATE(YEAR(D13),MONTH(D13)+9,DAY(D13))),"") | E25: =IF(D10="","",IF(9>D12,"",D10))
B26: 10 | C26: =IF(D12="","",IF(10>D12,"","Monthly Instalment "&10)) | D26: =IFERROR(IF(D13="","",DATE(YEAR(D13),MONTH(D13)+10,DAY(D13))),"") | E26: =IF(D10="","",IF(10>D12,"",D10))
B27: 11 | C27: =IF(D12="","",IF(11>D12,"","Monthly Instalment "&11)) | D27: =IFERROR(IF(D13="","",DATE(YEAR(D13),MONTH(D13)+11,DAY(D13))),"") | E27: =IF(D10="","",IF(11>D12,"",D10))
B28: 12 | C28: =IF(D12="","",IF(12>D12,"","Monthly Instalment "&12)) | D28: =IFERROR(IF(D13="","",DATE(YEAR(D13),MONTH(D13)+12,DAY(D13))),"") | E28: =IF(D10="","",IF(12>D12,"",D10))
B29: 13 | C29: =IF(D12="","",IF(13>D12,"","Monthly Instalment "&13)) | D29: =IFERROR(IF(D13="","",DATE(YEAR(D13),MONTH(D13)+13,DAY(D13))),"") | E29: =IF(D10="","",IF(13>D12,"",D10))
B30: 14 | C30: =IF(D12="","",IF(14>D12,"","Monthly Instalment "&14)) | D30: =IFERROR(IF(D13="","",DATE(YEAR(D13),MONTH(D13)+14,DAY(D13))),"") | E30: =IF(D10="","",IF(14>D12,"",D10))
B31: 15 | C31: =IF(D12="","",IF(15>D12,"","Monthly Instalment "&15)) | D31: =IFERROR(IF(D13="","",DATE(YEAR(D13),MONTH(D13)+15,DAY(D13))),"") | E31: =IF(D10="","",IF(15>D12,"",D10))
B32: 16 | C32: =IF(D12="","",IF(16>D12,"","Monthly Instalment "&16)) | D32: =IFERROR(IF(D13="","",DATE(YEAR(D13),MONTH(D13)+16,DAY(D13))),"") | E32: =IF(D10="","",IF(16>D12,"",D10))
B33: 17 | C33: =IF(D12="","",IF(17>D12,"","Monthly Instalment "&17)) | D33: =IFERROR(IF(D13="","",DATE(YEAR(D13),MONTH(D13)+17,DAY(D13))),"") | E33: =IF(D10="","",IF(17>D12,"",D10))
B34: 18 | C34: =IF(D12="","",IF(18>D12,"","Monthly Instalment "&18)) | D34: =IFERROR(IF(D13="","",DATE(YEAR(D13),MONTH(D13)+18,DAY(D13))),"") | E34: =IF(D10="","",IF(18>D12,"",D10))
B35: 19 | C35: =IF(D12="","",IF(19>D12,"","Monthly Instalment "&19)) | D35: =IFERROR(IF(D13="","",DATE(YEAR(D13),MONTH(D13)+19,DAY(D13))),"") | E35: =IF(D10="","",IF(19>D12,"",D10))
B36: 20 | C36: =IF(D12="","",IF(20>D12,"","Monthly Instalment "&20)) | D36: =IFERROR(IF(D13="","",DATE(YEAR(D13),MONTH(D13)+20,DAY(D13))),"") | E36: =IF(D10="","",IF(20>D12,"",D10))
B37: 21 | C37: =IF(D12="","",IF(21>D12,"","Monthly Instalment "&21)) | D37: =IFERROR(IF(D13="","",DATE(YEAR(D13),MONTH(D13)+21,DAY(D13))),"") | E37: =IF(D10="","",IF(21>D12,"",D10))
B38: 22 | C38: =IF(D12="","",IF(22>D12,"","Monthly Instalment "&22)) | D38: =IFERROR(IF(D13="","",DATE(YEAR(D13),MONTH(D13)+22,DAY(D13))),"") | E38: =IF(D10="","",IF(22>D12,"",D10))
B39: 23 | C39: =IF(D12="","",IF(23>D12,"","Monthly Instalment "&23)) | D39: =IFERROR(IF(D13="","",DATE(YEAR(D13),MONTH(D13)+23,DAY(D13))),"") | E39: =IF(D10="","",IF(23>D12,"",D10))
B40: 24 | C40: =IF(D12="","",IF(24>D12,"","Monthly Instalment "&24)) | D40: =IFERROR(IF(D13="","",DATE(YEAR(D13),MONTH(D13)+24,DAY(D13))),"") | E40: =IF(D10="","",IF(24>D12,"",D10))
B41: 25 | C41: =IF(D12="","",IF(25>D12,"","Monthly Instalment "&25)) | D41: =IFERROR(IF(D13="","",DATE(YEAR(D13),MONTH(D13)+25,DAY(D13))),"") | E41: =IF(D10="","",IF(25>D12,"",D10))
B42: 26 | C42: =IF(D12="","",IF(26>D12,"","Monthly Instalment "&26)) | D42: =IFERROR(IF(D13="","",DATE(YEAR(D13),MONTH(D13)+26,DAY(D13))),"") | E42: =IF(D10="","",IF(26>D12,"",D10))
B43: 27 | C43: =IF(D12="","",IF(27>D12,"","Monthly Instalment "&27)) | D43: =IFERROR(IF(D13="","",DATE(YEAR(D13),MONTH(D13)+27,DAY(D13))),"") | E43: =IF(D10="","",IF(27>D12,"",D10))
...

Sheet CLIENT COPY
B1: 🏢 BEST TIME MARKETING OFFICIAL BOOKING CONFIRMATION
B2: Enter Deal ID in cell C4 → entire form auto-fills
B4: Deal ID:
B6: PLOT DETAILS
B7: Project | C7: =IFERROR(INDEX('DATA ENTRY'!$C:$C,MATCH(C4,'DATA ENTRY'!$B:$B,0)),"") -> 0
B8: Dare / Block | C8: =IFERROR(INDEX('DATA ENTRY'!$D:$D,MATCH(C4,'DATA ENTRY'!$B:$B,0)),"") -> 0
B9: Plot No. | C9: =IFERROR(INDEX('DATA ENTRY'!$E:$E,MATCH(C4,'DATA ENTRY'!$B:$B,0)),"") -> 0
B10: Size | C10: =IFERROR(INDEX('DATA ENTRY'!$F:$F,MATCH(C4,'DATA ENTRY'!$B:$B,0)),"") -> 0
B11: Type (Res/Comm) | C11: =IFERROR(INDEX('DATA ENTRY'!$G:$G,MATCH(C4,'DATA ENTRY'!$B:$B,0)),"") -> 0
B12: APPLICANT
B13: Applicant Name | C13: =IFERROR(INDEX('DATA ENTRY'!$S:$S,MATCH(C4,'DATA ENTRY'!$B:$B,0)),"") -> 0
B14: Father's Name | C14: =IFERROR(INDEX('DATA ENTRY'!$T:$T,MATCH(C4,'DATA ENTRY'!$B:$B,0)),"") -> 0
B15: CNIC No. | C15: =IFERROR(INDEX('DATA ENTRY'!$V:$V,MATCH(C4,'DATA ENTRY'!$B:$B,0)),"") -> 0
B16: Mobile No. | C16: =IFERROR(INDEX('DATA ENTRY'!$W:$W,MATCH(C4,'DATA ENTRY'!$B:$B,0)),"") -> 0
B17: PAYMENT PLAN
B18: Total Amount (PKR) | C18: =IFERROR(INDEX('DATA ENTRY'!$J:$J,MATCH(C4,'DATA ENTRY'!$B:$B,0)),"")
B19: Token / Advance (PKR) | C19: =IFERROR(INDEX('DATA ENTRY'!$K:$K,MATCH(C4,'DATA ENTRY'!$B:$B,0)),"") -> 0
B20: Monthly Instalment | C20: =IFERROR(INDEX('DATA ENTRY'!$M:$M,MATCH(C4,'DATA ENTRY'!$B:$B,0)),"")
B21: No. of Months | C21: =IFERROR(INDEX('DATA ENTRY'!$L:$L,MATCH(C4,'DATA ENTRY'!$B:$B,0)),"") -> 0
B22: Bubble Payment (PKR) | C22: =IFERROR(INDEX('DATA ENTRY'!$N:$N,MATCH(C4,'DATA ENTRY'!$B:$B,0)),"") -> 0
B23: NOMINEE
B24: Nominee Name | C24: =IFERROR(INDEX('DATA ENTRY'!$X:$X,MATCH(C4,'DATA ENTRY'!$B:$B,0)),"") -> 0
B25: Relation | C25: =IFERROR(INDEX('DATA ENTRY'!$Y:$Y,MATCH(C4,'DATA ENTRY'!$B:$B,0)),"") -> 0
B26: Nominee CNIC | C26: =IFERROR(INDEX('DATA ENTRY'!$AB:$AB,MATCH(C4,'DATA ENTRY'!$B:$B,0)),"") -> 0
B27: REGISTRY
B28: Registry Status | C28: =IFERROR(INDEX('DATA ENTRY'!$AO:$AO,MATCH(C4,'DATA ENTRY'!$B:$B,0)),"") -> 0
B29: Booking Date | C29: =IFERROR(INDEX('DATA ENTRY'!$AU:$AU,MATCH(C4,'DATA ENTRY'!$B:$B,0)),"") -> 0
B32: Authorised Signature: ________________________ | D32: Applicant Signature: ________________________
B34: This is an officially generated document by Best Time Marketing. For queries: 0300-XXXXXXX

Sheet 📊 DASHBOARD
A1: 📊 BEST TIME MARKETING — MANAGEMENT DASHBOARD
A2: =TODAY() -> 46116
A4: TOTAL DEALS | D4: TOTAL REVENUE (PKR) | G4: TOTAL RECEIVED (PKR) | J4: BALANCE DUE (PKR)
A5: =COUNTA('DATA ENTRY'!B4:B203) -> 200 | D5: =IFERROR(SUM('DATA ENTRY'!J4:J203),0) -> 0 | G5: =IFERROR(SUM('DATA ENTRY'!P4:P203),0) -> 0 | J5: =IFERROR(SUM('DATA ENTRY'!Q4:Q203),0) -> 0
A7: OVERDUE CLIENTS | D7: COMPLETED DEALS | G7: ACTIVE DEALS | J7: REGISTRY PENDING
A8: =COUNTIF('DATA ENTRY'!R4:R203,"*Overdue*") -> 0 | D8: =COUNTIF('DATA ENTRY'!R4:R203,"*Completed*") -> 0 | G8: =COUNTIF('DATA ENTRY'!R4:R203,"*Active*") -> 0 | J8: =COUNTIF('DATA ENTRY'!AO4:AO203,"Not Done")+COUNTIF('DATA ENTRY'!AO4:AO203,"Late") -> 0
A11: 📁 PROJECT-WISE SUMMARY | H11: 🔴 OVERDUE ALERTS (Top 10)
A12: Project | B12: Total Deals | C12: Revenue (PKR) | D12: Received (PKR) | E12: Balance (PKR) | F12: Overdue Count | H12: Deal ID | I12: Client | J12: Project | K12: Balance | L12: Overdue Since
A13: Green Valley | B13: =COUNTIF('DATA ENTRY'!C4:C203,SETTINGS!C5) -> 0 | C13: =SUMIF('DATA ENTRY'!C4:C203,SETTINGS!C5,'DATA ENTRY'!J4:J203) -> 0 | D13: =SUMIF('DATA ENTRY'!C4:C203,SETTINGS!C5,'DATA ENTRY'!P4:P203) -> 0 | E13: =SUMIF('DATA ENTRY'!C4:C203,SETTINGS!C5,'DATA ENTRY'!Q4:Q203) -> 0 | F13: =COUNTIFS('DATA ENTRY'!C4:C203,SETTINGS!C5,'DATA ENTRY'!R4:R203,"*Overdue*") -> 0 | H13: =IFERROR(INDEX('DATA ENTRY'!$B:$B,SMALL(IF('DATA ENTRY'!$R$4:$R$203="🔴 Overdue",ROW('DATA ENTRY'!$R$4:$R$203)),1)),"") | I13: =IFERROR(INDEX('DATA ENTRY'!$S:$S,SMALL(IF('DATA ENTRY'!$R$4:$R$203="🔴 Overdue",ROW('DATA ENTRY'!$R$4:$R$203)),1)),"") -> 0 | J13: =IFERROR(INDEX('DATA ENTRY'!$C:$C,SMALL(IF('DATA ENTRY'!$R$4:$R$203="🔴 Overdue",ROW('DATA ENTRY'!$R$4:$R$203)),1)),"") -> 0 | K13: =IFERROR(INDEX('DATA ENTRY'!$Q:$Q,SMALL(IF('DATA ENTRY'!$R$4:$R$203="🔴 Overdue",ROW('DATA ENTRY'!$R$4:$R$203)),1)),"")
A14: Sky Heights | B14: =COUNTIF('DATA ENTRY'!C4:C203,SETTINGS!C6) -> 0 | C14: =SUMIF('DATA ENTRY'!C4:C203,SETTINGS!C6,'DATA ENTRY'!J4:J203) -> 0 | D14: =SUMIF('DATA ENTRY'!C4:C203,SETTINGS!C6,'DATA ENTRY'!P4:P203) -> 0 | E14: =SUMIF('DATA ENTRY'!C4:C203,SETTINGS!C6,'DATA ENTRY'!Q4:Q203) -> 0 | F14: =COUNTIFS('DATA ENTRY'!C4:C203,SETTINGS!C6,'DATA ENTRY'!R4:R203,"*Overdue*") -> 0 | H14: =IFERROR(INDEX('DATA ENTRY'!$B:$B,SMALL(IF('DATA ENTRY'!$R$4:$R$203="🔴 Overdue",ROW('DATA ENTRY'!$R$4:$R$203)),2)),"") | I14: =IFERROR(INDEX('DATA ENTRY'!$S:$S,SMALL(IF('DATA ENTRY'!$R$4:$R$203="🔴 Overdue",ROW('DATA ENTRY'!$R$4:$R$203)),2)),"") | J14: =IFERROR(INDEX('DATA ENTRY'!$C:$C,SMALL(IF('DATA ENTRY'!$R$4:$R$203="🔴 Overdue",ROW('DATA ENTRY'!$R$4:$R$203)),2)),"") | K14: =IFERROR(INDEX('DATA ENTRY'!$Q:$Q,SMALL(IF('DATA ENTRY'!$R$4:$R$203="🔴 Overdue",ROW('DATA ENTRY'!$R$4:$R$203)),2)),"")
A15: Sunrise City | B15: =COUNTIF('DATA ENTRY'!C4:C203,SETTINGS!C7) -> 0 | C15: =SUMIF('DATA ENTRY'!C4:C203,SETTINGS!C7,'DATA ENTRY'!J4:J203) -> 0 | D15: =SUMIF('DATA ENTRY'!C4:C203,SETTINGS!C7,'DATA ENTRY'!P4:P203) -> 0 | E15: =SUMIF('DATA ENTRY'!C4:C203,SETTINGS!C7,'DATA ENTRY'!Q4:Q203) -> 0 | F15: =COUNTIFS('DATA ENTRY'!C4:C203,SETTINGS!C7,'DATA ENTRY'!R4:R203,"*Overdue*") -> 0 | H15: =IFERROR(INDEX('DATA ENTRY'!$B:$B,SMALL(IF('DATA ENTRY'!$R$4:$R$203="🔴 Overdue",ROW('DATA ENTRY'!$R$4:$R$203)),3)),"") | I15: =IFERROR(INDEX('DATA ENTRY'!$S:$S,SMALL(IF('DATA ENTRY'!$R$4:$R$203="🔴 Overdue",ROW('DATA ENTRY'!$R$4:$R$203)),3)),"") | J15: =IFERROR(INDEX('DATA ENTRY'!$C:$C,SMALL(IF('DATA ENTRY'!$R$4:$R$203="🔴 Overdue",ROW('DATA ENTRY'!$R$4:$R$203)),3)),"") | K15: =IFERROR(INDEX('DATA ENTRY'!$Q:$Q,SMALL(IF('DATA ENTRY'!$R$4:$R$203="🔴 Overdue",ROW('DATA ENTRY'!$R$4:$R$203)),3)),"")
A16: BTM Residencia | B16: =COUNTIF('DATA ENTRY'!C4:C203,SETTINGS!C8) -> 0 | C16: =SUMIF('DATA ENTRY'!C4:C203,SETTINGS!C8,'DATA ENTRY'!J4:J203) -> 0 | D16: =SUMIF('DATA ENTRY'!C4:C203,SETTINGS!C8,'DATA ENTRY'!P4:P203) -> 0 | E16: =SUMIF('DATA ENTRY'!C4:C203,SETTINGS!C8,'DATA ENTRY'!Q4:Q203) -> 0 | F16: =COUNTIFS('DATA ENTRY'!C4:C203,SETTINGS!C8,'DATA ENTRY'!R4:R203,"*Overdue*") -> 0 | H16: =IFERROR(INDEX('DATA ENTRY'!$B:$B,SMALL(IF('DATA ENTRY'!$R$4:$R$203="🔴 Overdue",ROW('DATA ENTRY'!$R$4:$R$203)),4)),"") | I16: =IFERROR(INDEX('DATA ENTRY'!$S:$S,SMALL(IF('DATA ENTRY'!$R$4:$R$203="🔴 Overdue",ROW('DATA ENTRY'!$R$4:$R$203)),4)),"") | J16: =IFERROR(INDEX('DATA ENTRY'!$C:$C,SMALL(IF('DATA ENTRY'!$R$4:$R$203="🔴 Overdue",ROW('DATA ENTRY'!$R$4:$R$203)),4)),"") | K16: =IFERROR(INDEX('DATA ENTRY'!$Q:$Q,SMALL(IF('DATA ENTRY'!$R$4:$R$203="🔴 Overdue",ROW('DATA ENTRY'!$R$4:$R$203)),4)),"")
A17: Elite Gardens | B17: =COUNTIF('DATA ENTRY'!C4:C203,SETTINGS!C9) -> 0 | C17: =SUMIF('DATA ENTRY'!C4:C203,SETTINGS!C9,'DATA ENTRY'!J4:J203) -> 0 | D17: =SUMIF('DATA ENTRY'!C4:C203,SETTINGS!C9,'DATA ENTRY'!P4:P203) -> 0 | E17: =SUMIF('DATA ENTRY'!C4:C203,SETTINGS!C9,'DATA ENTRY'!Q4:Q203) -> 0 | F17: =COUNTIFS('DATA ENTRY'!C4:C203,SETTINGS!C9,'DATA ENTRY'!R4:R203,"*Overdue*") -> 0 | H17: =IFERROR(INDEX('DATA ENTRY'!$B:$B,SMALL(IF('DATA ENTRY'!$R$4:$R$203="🔴 Overdue",ROW('DATA ENTRY'!$R$4:$R$203)),5)),"") | I17: =IFERROR(INDEX('DATA ENTRY'!$S:$S,SMALL(IF('DATA ENTRY'!$R$4:$R$203="🔴 Overdue",ROW('DATA ENTRY'!$R$4:$R$203)),5)),"") | J17: =IFERROR(INDEX('DATA ENTRY'!$C:$C,SMALL(IF('DATA ENTRY'!$R$4:$R$203="🔴 Overdue",ROW('DATA ENTRY'!$R$4:$R$203)),5)),"") | K17: =IFERROR(INDEX('DATA ENTRY'!$Q:$Q,SMALL(IF('DATA ENTRY'!$R$4:$R$203="🔴 Overdue",ROW('DATA ENTRY'!$R$4:$R$203)),5)),"")
H18: =IFERROR(INDEX('DATA ENTRY'!$B:$B,SMALL(IF('DATA ENTRY'!$R$4:$R$203="🔴 Overdue",ROW('DATA ENTRY'!$R$4:$R$203)),6)),"") | I18: =IFERROR(INDEX('DATA ENTRY'!$S:$S,SMALL(IF('DATA ENTRY'!$R$4:$R$203="🔴 Overdue",ROW('DATA ENTRY'!$R$4:$R$203)),6)),"") | J18: =IFERROR(INDEX('DATA ENTRY'!$C:$C,SMALL(IF('DATA ENTRY'!$R$4:$R$203="🔴 Overdue",ROW('DATA ENTRY'!$R$4:$R$203)),6)),"") | K18: =IFERROR(INDEX('DATA ENTRY'!$Q:$Q,SMALL(IF('DATA ENTRY'!$R$4:$R$203="🔴 Overdue",ROW('DATA ENTRY'!$R$4:$R$203)),6)),"")
H19: =IFERROR(INDEX('DATA ENTRY'!$B:$B,SMALL(IF('DATA ENTRY'!$R$4:$R$203="🔴 Overdue",ROW('DATA ENTRY'!$R$4:$R$203)),7)),"") | I19: =IFERROR(INDEX('DATA ENTRY'!$S:$S,SMALL(IF('DATA ENTRY'!$R$4:$R$203="🔴 Overdue",ROW('DATA ENTRY'!$R$4:$R$203)),7)),"") | J19: =IFERROR(INDEX('DATA ENTRY'!$C:$C,SMALL(IF('DATA ENTRY'!$R$4:$R$203="🔴 Overdue",ROW('DATA ENTRY'!$R$4:$R$203)),7)),"") | K19: =IFERROR(INDEX('DATA ENTRY'!$Q:$Q,SMALL(IF('DATA ENTRY'!$R$4:$R$203="🔴 Overdue",ROW('DATA ENTRY'!$R$4:$R$203)),7)),"")
H20: =IFERROR(INDEX('DATA ENTRY'!$B:$B,SMALL(IF('DATA ENTRY'!$R$4:$R$203="🔴 Overdue",ROW('DATA ENTRY'!$R$4:$R$203)),8)),"") | I20: =IFERROR(INDEX('DATA ENTRY'!$S:$S,SMALL(IF('DATA ENTRY'!$R$4:$R$203="🔴 Overdue",ROW('DATA ENTRY'!$R$4:$R$203)),8)),"") | J20: =IFERROR(INDEX('DATA ENTRY'!$C:$C,SMALL(IF('DATA ENTRY'!$R$4:$R$203="🔴 Overdue",ROW('DATA ENTRY'!$R$4:$R$203)),8)),"") | K20: =IFERROR(INDEX('DATA ENTRY'!$Q:$Q,SMALL(IF('DATA ENTRY'!$R$4:$R$203="🔴 Overdue",ROW('DATA ENTRY'!$R$4:$R$203)),8)),"")
H21: =IFERROR(INDEX('DATA ENTRY'!$B:$B,SMALL(IF('DATA ENTRY'!$R$4:$R$203="🔴 Overdue",ROW('DATA ENTRY'!$R$4:$R$203)),9)),"") | I21: =IFERROR(INDEX('DATA ENTRY'!$S:$S,SMALL(IF('DATA ENTRY'!$R$4:$R$203="🔴 Overdue",ROW('DATA ENTRY'!$R$4:$R$203)),9)),"") | J21: =IFERROR(INDEX('DATA ENTRY'!$C:$C,SMALL(IF('DATA ENTRY'!$R$4:$R$203="🔴 Overdue",ROW('DATA ENTRY'!$R$4:$R$203)),9)),"") | K21: =IFERROR(INDEX('DATA ENTRY'!$Q:$Q,SMALL(IF('DATA ENTRY'!$R$4:$R$203="🔴 Overdue",ROW('DATA ENTRY'!$R$4:$R$203)),9)),"")
H22: =IFERROR(INDEX('DATA ENTRY'!$B:$B,SMALL(IF('DATA ENTRY'!$R$4:$R$203="🔴 Overdue",ROW('DATA ENTRY'!$R$4:$R$203)),10)),"") | I22: =IFERROR(INDEX('DATA ENTRY'!$S:$S,SMALL(IF('DATA ENTRY'!$R$4:$R$203="🔴 Overdue",ROW('DATA ENTRY'!$R$4:$R$203)),10)),"") | J22: =IFERROR(INDEX('DATA ENTRY'!$C:$C,SMALL(IF('DATA ENTRY'!$R$4:$R$203="🔴 Overdue",ROW('DATA ENTRY'!$R$4:$R$203)),10)),"") | K22: =IFERROR(INDEX('DATA ENTRY'!$Q:$Q,SMALL(IF('DATA ENTRY'!$R$4:$R$203="🔴 Overdue",ROW('DATA ENTRY'!$R$4:$R$203)),10)),"")
